Workbook

Sheet 0. Readme
B2: Intersectional Impact Assessment Matrix
B3: Vision and Language AI · Working tool for the InterVisions project
B6: Purpose
B7: This workbook is the practical companion to the InterVisions Guidelines for an Intersectional Impact Assessment. It operationalises the analytical framework presented in the Guidelines into a structured matrix for assessing AI systems across their lifecycle. Rows correspond to the intersectional dimensions and subdimensions described in the Guidelines; columns correspond to the six areas analysed of the AI lifecycle.
B10: Structure of each cell
B11: Each (subdimension × phase) cell contains up to 4 questions: 1 yes/no opener plus up to 3 open follow-up questions. Within each cell the questions are ordered along the dimensional axis indicated in the row header (Short term → Long term · Reflection → Re-visioning · Mitigation → Accountability).
B14: Sheets in this workbook
B16: 0. Readme | C16: This page: purpose of the tool and how to navigate it.
B17: 1. Matrix | C17: The full 8×6 matrix with all questions.
B18: 2. Yes-No Checklist | C18: Compact checklist of all 48 yes/no openers (audit tool).
B19: 3. Scoring | C19: Scoring methodology and criteria.
B20: 4. Theoretical references | C20: Selected references from Chapter 9 (Charting Pathways, Ruiz García & Gómez).
B21: 5. Axes legend | C21: The three dimensional axes structuring the matrix.
B24: Project: InterVisions (101214711)
B25: CERV-2024-CHAR-LITI-CHARTER
B26: These guidelines were developed by the InterVisions consortium (ALIA-Donestech, Computer Vision Center and Diputació de Barcelona), with input from a dedicated Guidelines Working Group and an Advisory Board.
B35: Funded by the European Union. Views and opinions expressed are however those of the author(s) only and do not necessarily reflect those of the European Union or the European Education and Culture Executive Agency (EACEA). Neither the European Union nor EACEA can be held responsible for them.

Sheet 1. Matrix
A2: Integrated Intersectional Impact Assessment Matrix
A3: Grey cells = Yes/No opener question · White cells = Open follow-ups · Subcategories grouped by intersectional dimension
A5: Intersectional dimension | B5: Subdimension · Axis (within-cell ordering) | C5: PROBLEM FRAMING | D5: DATA & REPRESENTATION | E5: MODEL & DEVELOPMENT | F5: TEAMS & INSTITUTIONS | G5: PARTICIPATION | H5: IMPACT
A6: Life-Machine | B6: Iteration through the lifespan of the system ↧ Axis: Short term ───► Long term | C6: ↧ ordered along axis ↧ | D6: ↧ ordered along axis ↧ | E6: ↧ ordered along axis ↧ | F6: ↧ ordered along axis ↧ | G6: ↧ ordered along axis ↧ | H6: ↧ ordered along axis ↧
C7: Y/N · Have you scheduled an Intersectional Impact Assessment (IIA) at multiple moments of the project lifecycle? | D7: Y/N · Have you assessed dataset biases by group (under/over-represented populations) and used adapted Datasheets to document curation? | E7: Y/N · Have you scheduled iterative bias audits across architecture decisions, training and evaluation milestones? | F7: Y/N · Are continuous improvement loops embedded in team workflows for tracking biases and sociotechnical harms? | G7: Y/N · Are diverse stakeholders engaged in regular feedback loops across the entire project lifecycle, not only at the end? | H7: Y/N · Have you planned when and how you'll check for bias, harm and disparate impact after deployment?
C8: › Which populations could be affected directly or indirectly by this project, and how have they been identified? | D8: › Could the data collection itself cause harm, privacy invasions or community exclusion? | E8: › How could architecture or training decisions affect different groups differently? | F8: › How are emerging risks transferred between teams when project responsibilities shift? | G8: › Which groups are invited at each iteration moment, and how are participation barriers (financial, technological, care) addressed? | H8: › What unintended impacts have emerged in real-world contexts that were not visible in validation?
C9: › What structural, historical or social biases might shape the problem you intend to address? | D9: › What annotation guidelines protect against stereotyping and cultural bias? | E9: › Are model performance, fairness and harm metrics measured disaggregated by intersectional groups? | F9: › Do leadership and review structures support sustained iteration rather than one-off audits? | G9: › How does stakeholder feedback reshape goals, metrics and design decisions in subsequent iterations? | H9: › What changes are made to the system based on post-deployment feedback, and how are they documented?
C10: › How will you document foundational decisions, assumptions and trade-offs from the start (e.g., adapted Datasheets and Model Cards)? | D10: › What retrospective reviews are scheduled to detect exclusion patterns in curated data over time? | E10: › What documentation (adapted Model Cards) records training decisions, mitigations and pending risks? | F10: › How will institutional learning be preserved across iterations, hires and project transitions? | G10: › What evidence shows that participation has actually changed the project's trajectory across iterations? | H10: › What residual impacts will remain after the system is updated, retired or replaced, and how will they be mitigated?
B11: The human side of the machine ↧ Axis: Short term ───► Long term | C11: ↧ ordered along axis ↧ | D11: ↧ ordered along axis ↧ | E11: ↧ ordered along axis ↧ | F11: ↧ ordered along axis ↧ | G11: ↧ ordered along axis ↧ | H11: ↧ ordered along axis ↧
C12: Y/N · Has a positionality statement been produced identifying who is defining the problem and from which social positions, privileges and powers? | D12: Y/N · Are data annotators, curators and labelers working under fair, ethical and transparent labor conditions? | E12: Y/N · Are the experiences of affected communities incorporated into training decisions and model evaluation criteria? | F12: Y/N · Does the team reflect intersectional diversity and are working conditions equitable? | G12: Y/N · Are participants recognised, properly compensated and supported with adequate care, time and accessibility resources? | H12: Y/N · Are user safety, well-being and downstream labor effects monitored after deployment?
C13: › Which perspectives are absent from the framing stage and how will they be incorporated? | D13: › Have the labels and categories been co-defined with potentially affected communities rather than imported from existing schemas? | E13: › Who decides on architecture, parameters, evaluation framework and which iterations advance? | F13: › Are there salary transparency policies, equitable budgets for subcontracted/external workers, and pay-equity audits? | G13: › How are language, mobility, disability and digital-literacy barriers addressed for participants? | H13: › How are users from different regions, languages and cultures supported in real use?
C14: › How does the funding source align with the project's values, and could it bias decisions or amplify exclusions? | D14: › Can you use licensed data or data with ethical compensation arrangements for creators and contributors? | E14: › Is the system evaluated for accessibility (languages, abilities, digital-literacy levels)? | F14: › Are there safe, retaliation-free complaint mechanisms with clearly defined scope and accessible procedures? | G14: › Are co-design workshops structured so participants can shape research questions, not only respond to them? | H14: › What mechanisms exist to address harms, including job displacement and exploitation of creative labor?
C15: › What alternative formulations of the problem emerge when affected communities are consulted at framing? | D15: › Are there data stewardship or trust mechanisms that share governance with creators and communities? | E15: › How does the team's diversity (or lack of it) shape evaluation outcomes and what corrective actions follow? | F15: › How are care work, flexible schedules and parental leaves distributed and tracked across the team? | G15: › What measures protect participants from extractive participation, tokenism and emotional labor over-burdening? | H15: › Is the documentation comprehensible across different levels of technical and linguistic literacy?
B16: Critical self-reflexivity ↧ Axis: Short term ───► Long term | C16: ↧ ordered along axis ↧ | D16: ↧ ordered along axis ↧ | E16: ↧ ordered along axis ↧ | F16: ↧ ordered along axis ↧ | G16: ↧ ordered along axis ↧ | H16: ↧ ordered along axis ↧
C17: Y/N · Are there structured spaces for the team to reflect on positionality and how systems of oppression shape this project? | D17: Y/N · Has the team interrogated who has real sovereignty over the data: communities, the institution or technology providers? | E17: Y/N · Has the team examined which behaviours, identities or practices the model implicitly normalises as 'correct' or 'desirable'? | F17: Y/N · Are positionality statements and reflexivity workshops integrated as periodic team practice? | G17: Y/N · Does the team examine its own role and power dynamics within the participatory process itself? | H17: Y/N · Has the team mapped which institutional dependencies could make it politically difficult to retire the system even if harmful?
C18: › What ideological frameworks (efficiency, security, productivity, innovation) make the problem seem 'legitimate' to solve with AI? | D18: › What forms of non-digital, communal or situated knowledge are excluded because they cannot be 'datafied'? | E18: › Which worldviews become hegemonic when codified in a stable technical system? | F18: › How are interdisciplinary perspectives (technical + social science + community) protected from being marginalised in decision-making? | G18: › How do team members reflect on the differences between their own positions and those of participants? | H18: › Which previously human decisions are now delegated to automated systems, and what democratic deliberation is lost?
C19: › Which structural problems are being technicized rather than addressed through policy, rights or redistribution? | D19: › Which dependencies (cloud, foundational models, chips, platforms) are created or reinforced by data choices? | E19: › Who defines what counts as valid evidence, acceptable error, or tolerable harm during evaluation? | F19: › Are there interventions to address vertical and horizontal segregation as they emerge? | G19: › Are mechanisms in place to surface and address discomforts, conflicts or epistemic clashes during participation? | H19: › How does the system change relations between institutions and citizens (more control, less negotiation, less right to explanation)?
C20: › What model of society (more automated, surveilled, extractive, centralised) does this project reinforce, and which actors gain power from it? | D20: › What forms of extractivism (energetic, labor, cognitive, cultural) are made invisible in the data value chain? | E20: › What political conflicts are being resolved as if they were merely problems of technical performance? | F20: › How does the team make space for collective learning when biases or blind spots are identified? | G20: › How does the team avoid presenting consultation as co-design when authority remains centralised? | H20: › What human, organisational or community capacities are eroded when functions are permanently delegated to AI?
B21: Sustainability and environment ↧ Axis: Short term ───► Long term | C21: ↧ ordered along axis ↧ | D21: ↧ ordered along axis ↧ | E21: ↧ ordered along axis ↧ | F21: ↧ ordered along axis ↧ | G21: ↧ ordered along axis ↧ | H21: ↧ ordered along axis ↧
C22: Y/N · Has the project budgeted environmental advisory and considered non-technological alternatives with smaller ecological footprint? | D22: Y/N · Is there a strategy to clean unnecessary data and minimise long-term environmental costs of storage? | E22: Y/N · Is the energy, water and CO2 footprint of training documented and bounded by reduction targets? | F22: Y/N · Does the institution audit and report environmental impacts of subcontracted infrastructure (servers, providers)? | G22: Y/N · Are communities bearing environmental costs of the AI infrastructure consulted and represented in decisions? | H22: Y/N · Are operational and end-of-life environmental impacts continuously monitored and reported?
C23: › Does the funding model incentivise ecological efficiency or maximum scale and computational consumption? | D23: › What environmental impacts arise from the long-term storage, transfer and duplication of data? | E23: › Which design decisions prioritize performance or scientific prestige over environmental sustainability? | F23: › Are providers transparent about their long-term environmental impacts? | G23: › How are local impacts (water, energy, e-waste) communicated transparently to affected territories? | H23: › What environmental impacts emerge when millions of users operate the system continuously?
C24: › Could communities with environmental knowledge and commitment be consulted at framing? | D24: › Are there data kept by inertia whose social value does not justify the ecological cost? | E24: › Are 'good enough' smaller models discarded in favour of larger but more polluting ones, and why? | F24: › Are environmental criteria part of procurement and partnership decisions? | G24: › Are environmental advisors, ecologists or grassroots groups included in stakeholder mapping? | H24: › What material and energy waste is left when the system is updated or abandoned?
C25: › What 'green innovation' narratives might be hiding environmentally unsustainable practices? | D25: › Where are the data centres located and what impacts do they have on local water, energy and waste systems? | E25: › Is environmental impact treated as a success criterion at the same level as accuracy or performance? | F25: › Do regional equity assessments consider whether environmental burdens are shifted to vulnerable communities? | G25: › How is the ethic of reciprocity (rather than extraction) embedded in environmental governance? | H25: › Who is held ecologically accountable for cumulative impacts across the system's lifespan?
A26: Systemic-Political | B26: Implementing an intersectional approach ↧ Axis: Reflection ───► Re-visioning | C26: ↧ ordered along axis ↧ | D26: ↧ ordered along axis ↧ | E26: ↧ ordered along axis ↧ | F26: ↧ ordered along axis ↧ | G26: ↧ ordered along axis ↧ | H26: ↧ ordered along axis ↧
C27: Y/N · Has an intersectional analysis identified the social groups that may be affected, and the structural conditions of inequality? | D27: Y/N · Has the dataset been examined to identify which identities or experiences are simplified, pathologised or decontextualized when turned into variables? | E27: Y/N · Are intersectional fairness metrics (multidimensional, not single-axis) part of the model evaluation framework? | F27: Y/N · Does the team have access to standing intersectional advisory (internal or external) integrated with decision-making? | G27: Y/N · Are participatory processes designed to include groups at the intersection of multiple axes of marginalisation, not only single categories? | H27: Y/N · Are post-deployment outcomes monitored disaggregated by intersectional groups, with clear thresholds for re-training or retirement?
C28: › What are the root causes of intersectional bias relevant to this problem, and which actors generate them? | D28: › Which social relations become visible, legible and governable through the data, and which remain outside? | E28: › What social hierarchies become naturalised when learned as 'objective' patterns? | F28: › Are technical decisions accompanied by intersectional impact memos? | G28: › How is meaningful (not symbolic) participation guaranteed for communities at the margins? | H28: › How does the model reproduce or reinforce existing power imbalances in real use?
C29: › Which structural inequalities are being redefined as technical problems rather than political or social ones? | D29: › What harms or biases may emerge from inherited categories that do not reflect social complexity? | E29: › Once trained, of the biases identified, which are corrected and which are reproduced? | F29: › How is contextual analysis (social, political, economic, cultural) brought into team processes? | G29: › Which mechanisms exist to redistribute decision-making power towards under-represented intersectional groups? | H29: › Are there access barriers and unequal benefits across social groups in deployment?
C30: › What deep transformations beyond 'subgroup fairness' is the project aiming for? | D30: › Are intersectional axes used as analytical lenses (not only descriptive labels) when examining the data? | E30: › What social conflicts are transformed into problems of classification, prediction or optimisation? | F30: › What institutional changes (governance, hiring, leadership) does the project advocate for to sustain intersectional fairness? | G30: › How are barriers (economic, time, mobility, cultural) addressed to enable equitable participation? | H30: › Which groups would be most affected by the system's withdrawal, and how is that planned for?
B31: Data Feminism ↧ Axis: Reflection ───► Re-visioning | C31: ↧ ordered along axis ↧ | D31: ↧ ordered along axis ↧ | E31: ↧ ordered along axis ↧ | F31: ↧ ordered along axis ↧ | G31: ↧ ordered along axis ↧ | H31: ↧ ordered along axis ↧
C32: Y/N · At the framing stage, has the project identified who controls, benefits from, and is excluded by the data envisioned? | D32: Y/N · Have you examined how data collection, annotation, filtering and interpretation reflect existing power structures? | E32: Y/N · Have binary or hierarchical categorical assumptions in model design been identified and challenged? | F32: Y/N · Are care work and the geographies of data labour explicitly considered in team composition, contracts and budgets? | G32: Y/N · Are communities in vulnerable positions involved in the creation, annotation and analysis of datasets in meaningful ways? | H32: Y/N · Are there responsibilities formally assigned for repairing symbolic and not only technical harms?
C33: › From which social experiences is 'the problem' defined as worth converting into data? | D33: › Whose voices, experiences or realities are silenced in the data production process? | E33: › Which voices, experiences or realities are silenced during training? | F33: › Which geographies produce data and which extract, process and capitalise on it within the institution? | G33: › How is the participation of these communities made meaningful and not symbolic? | H33: › What memories, traumas or stigmas might become permanently inscribed in the data systems?
C34: › What axes of inequality and systems of oppression operate in the problem you want to address? | D34: › How are rigid categories (binary gender, fixed class, simplified race) replaced with more inclusive, intersectional ones? | E34: › Whose labor is performed during training and evaluation, and how is it recognised? | F34: › Which infrastructures of the institution reinforce centre-periphery relations in knowledge production? | G34: › Which working and care conditions of contributors are made visible and supported? | H34: › Who can interpret or contest the system's results in everyday practice?
C35: › How will care work and emotional/embodied knowledge be valued in framing the data work? | D35: › How is the labor of annotators, cleaners and curators recognised or invisibilised in the data pipeline? | E35: › Which identities become invisible when they cannot be adequately represented in the model's outputs? | F35: › How does the institution acknowledge and address contributions from communities who provide knowledge without recognition or benefit? | G35: › Who gains symbolic, economic or political power from the data produced, and is this redistributed? | H35: › How does the meaning of data shift when it is used in contexts different from those of its production?
A36: Methods-Metrics | B36: Participatory AI ↧ Axis: Mitigation ───► Accountability | C36: ↧ ordered along axis ↧ | D36: ↧ ordered along axis ↧ | E36: ↧ ordered along axis ↧ | F36: ↧ ordered along axis ↧ | G36: ↧ ordered along axis ↧ | H36: ↧ ordered along axis ↧
C37: Y/N · Have the relevant communities and stakeholders that may be affected by these technologies been mapped at framing? | D37: Y/N · Was the kind of data to be collected, and the labels to be used, decided with active participation of the communities concerned? | E37: Y/N · Have affected communities retained governance over their data during training (e.g., federated learning, data trusts)? | F37: Y/N · Is participation, co-design and stakeholder engagement work built into job descriptions, budgets and timelines, not just added on afterwards? | G37: Y/N · Are co-design workshops and continuous feedback loops the primary participation methods, with documented influence on outcomes? | H37: Y/N · Is participation a constant, long-term strategy with continuous feedback during deployment and end-of-life?
C38: › Which voices may be missing in this initial phase, and how will they be integrated? | D38: › Are the tools used for annotation, communication and training of participants accessible and accepted by them? | E38: › Has the model objective function (loss weights, vocabulary, tokenisation) been discussed with the participant group? | F38: › Does the team include participation specialists, social scientists and community liaisons alongside technical staff? | G38: › How is the diversity of participants measured (Stakeholder Diversity Index, Participation Equity Score)? | H38: › Are vulnerable communities involved in the development of monitoring and re-training strategies?
C39: › Does the project motivation reflect concerns explicitly expressed by diverse stakeholders? | D39: › Has the community been consulted about potential information loss during preprocessing and curation? | E39: › Are technical decisions and their consequences documented and accessible to participants and affected groups? | F39: › How is the institution accountable for the time, care and follow-up that meaningful participation requires? | G39: › What barriers to participation (financial, technological, care, time) are tracked and mitigated? | H39: › Were stakeholders consulted on decisions to finalize, replace or retire the system, and on transitions?
C40: › How will participants receive valuable compensation for their contribution? | D40: › Are there verification or human-in-the-loop checkpoints during preprocessing and curation? | E40: › Are the evaluation goals and metrics aligned with the interests of the affected population? | F40: › Are there clear protocols for sharing decision-making authority with stakeholders, and how are conflicts resolved? | G40: › How is participant satisfaction with the participatory process itself evaluated and acted upon? | H40: › Is any of the participatory input being lost across iterations or versions over time?
B41: Scales of value and knowledge ↧ Axis: Mitigation ───► Accountability | C41: ↧ ordered along axis ↧ | D41: ↧ ordered along axis ↧ | E41: ↧ ordered along axis ↧ | F41: ↧ ordered along axis ↧ | G41: ↧ ordered along axis ↧ | H41: ↧ ordered along axis ↧
C42: Y/N · Is it explicit who decides which problem is most important and which conception of 'value' (economic, social, symbolic, spiritual) legitimises this project over alternatives? | D42: Y/N · Has the team examined which types of knowledge become inscribed in the data infrastructure as 'standards', and which become impractical? | E42: Y/N · Has the team made explicit which theory of the world (deterministic, probabilistic, mechanistic, behavioural) is privileged in modelling? | F42: Y/N · Does the institution recognise plural forms of expertise (technical + situated + ancestral + experiential) when designing methods? | G42: Y/N · Have community stakeholders had a real say in the methods and metrics used to judge this project? | H42: Y/N · Are there mechanisms to track which forms of knowledge become institutionalised through the system, and which disappear?
...

Sheet 2. Yes-No Checklist
A2: Yes/No audit checklist · 48 opener questions
A3: One row per (subdimension × phase) cell. Use the Notes column to record evidence and follow-ups.
A5: DIMENSION | B5: SUBDIMENSION | C5: PHASE | D5: YES/NO QUESTION | E5: Y / N / NA | F5: NOTES & EVIDENCE
A6: Life-Machine | B6: Iteration through the lifespan of the system | C6: Problem framing | D6: Have you scheduled an Intersectional Impact Assessment (IIA) at multiple moments of the project lifecycle?
A7: Life-Machine | B7: Iteration through the lifespan of the system | C7: Data & representation | D7: Have you assessed dataset biases by group (under/over-represented populations) and used adapted Datasheets to document curation?
A8: Life-Machine | B8: Iteration through the lifespan of the system | C8: Model & development | D8: Have you scheduled iterative bias audits across architecture decisions, training and evaluation milestones?
A9: Life-Machine | B9: Iteration through the lifespan of the system | C9: Teams & institutions | D9: Are continuous improvement loops embedded in team workflows for tracking biases and sociotechnical harms?
A10: Life-Machine | B10: Iteration through the lifespan of the system | C10: Participation | D10: Are diverse stakeholders engaged in regular feedback loops across the entire project lifecycle, not only at the end?
A11: Life-Machine | B11: Iteration through the lifespan of the system | C11: Impact | D11: Have you planned when and how you'll check for bias, harm and disparate impact after deployment?
A12: Life-Machine | B12: The Human Side of the Machine | C12: Problem framing | D12: Has a positionality statement been produced identifying who is defining the problem and from which social positions, privileges and powers?
A13: Life-Machine | B13: The Human Side of the Machine | C13: Data & representation | D13: Are data annotators, curators and labelers working under fair, ethical and transparent labor conditions?
A14: Life-Machine | B14: The Human Side of the Machine | C14: Model & development | D14: Are the experiences of affected communities incorporated into training decisions and model evaluation criteria?
A15: Life-Machine | B15: The Human Side of the Machine | C15: Teams & institutions | D15: Does the team reflect intersectional diversity and are working conditions equitable?
A16: Life-Machine | B16: The Human Side of the Machine | C16: Participation | D16: Are participants recognised, properly compensated and supported with adequate care, time and accessibility resources?
A17: Life-Machine | B17: The Human Side of the Machine | C17: Impact | D17: Are user safety, well-being and downstream labor effects monitored after deployment?
... A53: Methods-Metrics | B53: Scales of Value and Knowledge | C53: Impact | D53: Are there mechanisms to track which forms of knowledge become institutionalised through the system, and which disappear?

Sheet 3. Scoring
A2: Traffic-light scoring tab
A3: Score calculated based on the Y/N/NA responses in the "2. Yes-No Checklist" tab.
A5: A. Score by phase / area (green ≥75%, yellow 50–74%, red <50%)
A6: Phase / Area | B6: Yes Responses | C6: Applicable Questions (excluding N/A) | D6: % Yes | E6: Traffic light score
A7: Problem framing | B7: =COUNTIF('2. Yes-No Checklist'!E6,"Y")+COUNTIF('2. Yes-No Checklist'!E12,"Y")+COUNTIF('2. Yes-No Checklist'!E18,"Y")+COUNTIF('2. Yes-No Checklist'!E24,"Y")+COUNTIF('2. Yes-No Checklist'!E30,"Y")+COUNTIF('2. Yes-No Checklist'!E36,"Y")+COUNTIF('2. Yes-No Checklist'!E42,"Y")+COUNTIF('2. Yes-No Checklist'!E48,"Y") -> 0 | C7: =8-(COUNTIF('2. Yes-No Checklist'!E6,"NA")+COUNTIF('2. Yes-No Checklist'!E12,"NA")+COUNTIF('2. Yes-No Checklist'!E18,"NA")+COUNTIF('2. Yes-No Checklist'!E24,"NA")+COUNTIF('2. Yes-No Checklist'!E30,"NA")+COUNTIF('2. Yes-No Checklist'!E36,"NA")+COUNTIF('2. Yes-No Checklist'!E42,"NA")+COUNTIF('2. Yes-No Checklist'!E48,"NA")) -> 8 | D7: =IFERROR(B7/C7,0) -> 0 | E7: =IF(D7>=0.75,"Integrated ≥75%",IF(D7>=0.5,"Partially Integrated 50–74%","Not Integrated <50%")) -> Not Integrated <50%
A8: Data & representation | B8: =COUNTIF('2. Yes-No Checklist'!E7,"Y")+COUNTIF('2. Yes-No Checklist'!E13,"Y")+COUNTIF('2. Yes-No Checklist'!E19,"Y")+COUNTIF('2. Yes-No Checklist'!E25,"Y")+COUNTIF('2. Yes-No Checklist'!E31,"Y")+COUNTIF('2. Yes-No Checklist'!E37,"Y")+COUNTIF('2. Yes-No Checklist'!E43,"Y")+COUNTIF('2. Yes-No Checklist'!E49,"Y") -> 0 | C8: =8-(COUNTIF('2. Yes-No Checklist'!E7,"NA")+COUNTIF('2. Yes-No Checklist'!E13,"NA")+COUNTIF('2. Yes-No Checklist'!E19,"NA")+COUNTIF('2. Yes-No Checklist'!E25,"NA")+COUNTIF('2. Yes-No Checklist'!E31,"NA")+COUNTIF('2. Yes-No Checklist'!E37,"NA")+COUNTIF('2. Yes-No Checklist'!E43,"NA")+COUNTIF('2. Yes-No Checklist'!E49,"NA")) -> 8 | D8: =IFERROR(B8/C8,0) -> 0 | E8: =IF(D8>=0.75,"Integrated ≥75%",IF(D8>=0.5,"Partially Integrated 50–74%","Not Integrated <50%")) -> Not Integrated <50%
A9: Model & development | B9: =COUNTIF('2. Yes-No Checklist'!E8,"Y")+COUNTIF('2. Yes-No Checklist'!E14,"Y")+COUNTIF('2. Yes-No Checklist'!E20,"Y")+COUNTIF('2. Yes-No Checklist'!E26,"Y")+COUNTIF('2. Yes-No Checklist'!E32,"Y")+COUNTIF('2. Yes-No Checklist'!E38,"Y")+COUNTIF('2. Yes-No Checklist'!E44,"Y")+COUNTIF('2. Yes-No Checklist'!E50,"Y") -> 0 | C9: =8-(COUNTIF('2. Yes-No Checklist'!E8,"NA")+COUNTIF('2. Yes-No Checklist'!E14,"NA")+COUNTIF('2. Yes-No Checklist'!E20,"NA")+COUNTIF('2. Yes-No Checklist'!E26,"NA")+COUNTIF('2. Yes-No Checklist'!E32,"NA")+COUNTIF('2. Yes-No Checklist'!E38,"NA")+COUNTIF('2. Yes-No Checklist'!E44,"NA")+COUNTIF('2. Yes-No Checklist'!E50,"NA")) -> 8 | D9: =IFERROR(B9/C9,0) -> 0 | E9: =IF(D9>=0.75,"Integrated ≥75%",IF(D9>=0.5,"Partially Integrated 50–74%","Not Integrated <50%")) -> Not Integrated <50%
A10: Teams & institutions | B10: =COUNTIF('2. Yes-No Checklist'!E9,"Y")+COUNTIF('2. Yes-No Checklist'!E15,"Y")+COUNTIF('2. Yes-No Checklist'!E21,"Y")+COUNTIF('2. Yes-No Checklist'!E27,"Y")+COUNTIF('2. Yes-No Checklist'!E33,"Y")+COUNTIF('2. Yes-No Checklist'!E39,"Y")+COUNTIF('2. Yes-No Checklist'!E45,"Y")+COUNTIF('2. Yes-No Checklist'!E51,"Y") -> 0 | C10: =8-(COUNTIF('2. Yes-No Checklist'!E9,"NA")+COUNTIF('2. Yes-No Checklist'!E15,"NA")+COUNTIF('2. Yes-No Checklist'!E21,"NA")+COUNTIF('2. Yes-No Checklist'!E27,"NA")+COUNTIF('2. Yes-No Checklist'!E33,"NA")+COUNTIF('2. Yes-No Checklist'!E39,"NA")+COUNTIF('2. Yes-No Checklist'!E45,"NA")+COUNTIF('2. Yes-No Checklist'!E51,"NA")) -> 8 | D10: =IFERROR(B10/C10,0) -> 0 | E10: =IF(D10>=0.75,"Integrated ≥75%",IF(D10>=0.5,"Partially Integrated 50–74%","Not Integrated <50%")) -> Not Integrated <50%
A11: Participation | B11: =COUNTIF('2. Yes-No Checklist'!E10,"Y")+COUNTIF('2. Yes-No Checklist'!E16,"Y")+COUNTIF('2. Yes-No Checklist'!E22,"Y")+COUNTIF('2. Yes-No Checklist'!E28,"Y")+COUNTIF('2. Yes-No Checklist'!E34,"Y")+COUNTIF('2. Yes-No Checklist'!E40,"Y")+COUNTIF('2. Yes-No Checklist'!E46,"Y")+COUNTIF('2. Yes-No Checklist'!E52,"Y") -> 0 | C11: =8-(COUNTIF('2. Yes-No Checklist'!E10,"NA")+COUNTIF('2. Yes-No Checklist'!E16,"NA")+COUNTIF('2. Yes-No Checklist'!E22,"NA")+COUNTIF('2. Yes-No Checklist'!E28,"NA")+COUNTIF('2. Yes-No Checklist'!E34,"NA")+COUNTIF('2. Yes-No Checklist'!E40,"NA")+COUNTIF('2. Yes-No Checklist'!E46,"NA")+COUNTIF('2. Yes-No Checklist'!E52,"NA")) -> 8 | D11: =IFERROR(B11/C11,0) -> 0 | E11: =IF(D11>=0.75,"Integrated ≥75%",IF(D11>=0.5,"Partially Integrated 50–74%","Not Integrated <50%")) -> Not Integrated <50%
A12: Impact | B12: =COUNTIF('2. Yes-No Checklist'!E11,"Y")+COUNTIF('2. Yes-No Checklist'!E17,"Y")+COUNTIF('2. Yes-No Checklist'!E23,"Y")+COUNTIF('2. Yes-No Checklist'!E29,"Y")+COUNTIF('2. Yes-No Checklist'!E35,"Y")+COUNTIF('2. Yes-No Checklist'!E41,"Y")+COUNTIF('2. Yes-No Checklist'!E47,"Y")+COUNTIF('2. Yes-No Checklist'!E53,"Y") -> 0 | C12: =8-(COUNTIF('2. Yes-No Checklist'!E11,"NA")+COUNTIF('2. Yes-No Checklist'!E17,"NA")+COUNTIF('2. Yes-No Checklist'!E23,"NA")+COUNTIF('2. Yes-No Checklist'!E29,"NA")+COUNTIF('2. Yes-No Checklist'!E35,"NA")+COUNTIF('2. Yes-No Checklist'!E41,"NA")+COUNTIF('2. Yes-No Checklist'!E47,"NA")+COUNTIF('2. Yes-No Checklist'!E53,"NA")) -> 8 | D12: =IFERROR(B12/C12,0) -> 0 | E12: =IF(D12>=0.75,"Integrated ≥75%",IF(D12>=0.5,"Partially Integrated 50–74%","Not Integrated <50%")) -> Not Integrated <50%
A15: B. Score by dimension (green ≥75%, yellow 50–74%, red <50%)
A16: Dimension | B16: Yes Responses | C16: Applicable Questions (excluding N/A) | D16: % Yes | E16: Traffic light score
A17: Life-Machine | B17: =COUNTIF('2. Yes-No Checklist'!E6:E29,"Y") -> 0 | C17: =24-COUNTIF('2. Yes-No Checklist'!E6:E29,"NA") -> 24 | D17: =IFERROR(B17/C17,0) -> 0 | E17: =IF(D17>=0.75,"Integrated ≥75%",IF(D17>=0.5,"Partially Integrated 50–74%","Not Integrated <50%")) -> Not Integrated <50%
A18: Systemic-Political | B18: =COUNTIF('2. Yes-No Checklist'!E30:E41,"Y") -> 0 | C18: =12-COUNTIF('2. Yes-No Checklist'!E30:E41,"NA") -> 12 | D18: =IFERROR(B18/C18,0) -> 0 | E18: =IF(D18>=0.75,"Integrated ≥75%",IF(D18>=0.5,"Partially Integrated 50–74%","Not Integrated <50%")) -> Not Integrated <50%
A19: Methods-Metrics | B19: =COUNTIF('2. Yes-No Checklist'!E42:E53,"Y") -> 0 | C19: =12-COUNTIF('2. Yes-No Checklist'!E42:E53,"NA") -> 12 | D19: =IFERROR(B19/C19,0) -> 0 | E19: =IF(D19>=0.75,"Integrated ≥75%",IF(D19>=0.5,"Partially Integrated 50–74%","Not Integrated <50%")) -> Not Integrated <50%
A22: C. Overall Assessment Score
B23: Yes Responses | C23: Applicable Questions (excluding N/A) | D23: % Yes | E23: Traffic light score
A24: Total IIA (48 questions) | B24: =COUNTIF('2. Yes-No Checklist'!E6:E53,"Y") -> 0 | C24: =48-COUNTIF('2. Yes-No Checklist'!E6:E53,"NA") -> 48 | D24: =IFERROR(B24/C24,0) -> 0 | E24: =IF(D24>=0.75,"Integrated ≥75%",IF(D24>=0.5,"Partially Integrated 50–74%","Not Integrated <50%")) -> Not Integrated <50%
A28: Traffic light system legend (Has the intersectional perspective been integrated?)
A29: Green (Integrated) | B29: Dimension/Overall: ≥75% Yes responses
A30: Yellow (Partially Integrated) | B30: Dimension/Overall: 50–74% Yes responses
A31: Red (Not Integrated) | B31: Dimension/Overall: <50% Yes responses
A32: NA | B32: N/A responses are excluded from the denominator (i.e. non-applicable questions)

Sheet 4. Theoretical references
A1: Theoretical references - Chapter 9 (Charting Pathways)
A2: Selected references and concepts from: Sonia Ruiz García & Lluis Gómez (2025). 'Charting Pathways: An Intersectional Impact Assessment for Vision and Language Foundation Models'. In Women, Technology, and Power: Unmasking (and Dealing with) Digital Disparities (Ch.9, pp. 225-253).
A4: SECTION | B4: CONCEPT / PRACTICE | C4: CITED WORKS IN THE CHAPTER
A5: §4.1 Iteration through the lifespan | B5: Ongoing monitoring at the 'full pipeline'; Datasheets and Model Cards adapted; ex-ante / ex-post evaluations; regular feedback loops. | C5: D'Ignazio & Klein (2019); Ada Lovelace Institute (2020); Ovalle et al. (2023); Collins & Bilge (2020); UNESCO (2023); Gebru et al. (2018); Mitchell et al. (2019).
A6: §4.1 The Human Side of the Machine | B6: Who designs / annotates / trains / evaluates; team diversity audits; placing people at the centre; accessibility assessments; labour-practices review. | C6: Civic (2022); James (2022); Rode (2011).
A7: §4.1 Critical Self-reflexivity | B7: Positionality statements; reflexivity workshops; team composition and working conditions; intersectional pay-gap and segregation metrics. | C7: Civic (2022); Klumbytė, Draude, & Taylor, 2022.
A8: §4.1 Sustainability and Environment | B8: Environmental impact audits; sustainable AI development; regional equity assessments; rethinking human-environment relations. | C8: Ren & Wierman (2024); Lacoste et al. (2019); Moro et al. (2023); Lenherr et al. (2021); Lewis et al. (2023).
A9: §4.2 Implementing an Intersectional Approach | B9: Identify root causes of bias; widen the conceptualisation of fairness beyond subgroup fairness; contextual analysis; foster systemic change. | C9: Collins & Bilge (2020).
A10: §4.2 Data Feminism | B10: 7 principles: examining/challenging power; valuing emotion and embodiment; rethinking binaries and hierarchies; embracing pluralism; situated knowledge; making labor visible. Participatory data practices. | C10: D'Ignazio & Klein (2019); Suresh et al. (2022); Civic (2022); Kak & Myers West (2023).
A11: §4.3 Participatory AI | B11: Stakeholder mapping; co-design workshops; cross-disciplinary collaboration; inclusive decision-making; Feedback mechanisms. Metrics: Stakeholder Diversity Index, Participation Equity Score, Barriers to Participation, Stakeholder Satisfaction Index, Decision-Making Democratic Score. | C11: Civic (2022); Suresh (2022); Ovalle (2023); Collins & Bilge (2020); Zárate (2021); Ruiz et al. (2023).
A12: §4.3 Scales of Value and Knowledge | B12: Participatory design of methods and metrics; bringing situated, everyday and ancestral knowledges. Metrics: Social Inequality, Intersecting Power Relations, Social Context, Relationality, Social Justice, Complexity & Bias, Fairness for Ranked Outputs (NDCG). | C12: Buolamwini et al. (2018); Suresh et al. (2019); Blodgett et al. (2020); Raj & Ekstrand (2022); Corbett-Davies (2023); D'Ignazio & Klein (2019); Civic (2022); Ovalle et al. (2023).

Sheet 5. Axes legend
B1: Dimensional axes - used to order questions within each cell
B2: Within each cell, the 4 questions (1 yes/no opener + up to 3 open follow-ups) are ordered along the axis of their main intersectional dimension. The opener is the most basic gateway check; the follow-ups deepen and broaden along the axis.
B4: Dimension | C4: From | D4: → | E4: To
B5: Life-Machine | C5: Short term | D5: → | E5: Long term
B6: Systemic-Political | C6: Reflection | D6: → | E6: Re-visioning
B7: Methods-Metrics | C7: Mitigation | D7: → | E7: Accountability
B10: HOW TO READ EACH CELL
B11: 1. Grey opener (Y/N) - the foundational compliance question.
B12: 2. First open follow-up - closest to the 'From' end of the axis (immediate, mitigation-oriented, short-term).
B13: 3. Second open follow-up - middle of the axis (deeper inquiry, structural).
B14: 4. Third open follow-up - closest to the 'To' end of the axis (re-visioning, accountability, long-term effects).
